<?xml version="1.0" encoding="utf-8"?>
<!-- This URDF was automatically created by SolidWorks to URDF Exporter! Originally created by Stephen Brawner (brawner@gmail.com) 
     Commit Version: 1.5.1-0-g916b5db  Build Version: 1.5.7152.31018
     For more information, please see http://wiki.ros.org/sw_urdf_exporter -->
<robot
  name="PP">

  <material name="white">
    <color rgba="0.9499 0.9499 0.9499 1"/>
  </material>

  <material name="light-pink">
    <color rgba="0.7725 0.5411 0.7725 1"/>
  </material>

  <link
    name="base_link">
    <inertial>
      <origin
        xyz="0.0019147 -1.044E-05 0.012436"
        rpy="0 0 0" />
      <mass
        value="0.95" />
      <inertia
        ixx="0.00090019"
        ixy="-3.9096E-07"
        ixz="-9.0854E-05"
        iyy="0.0028213"
        iyz="1.8688E-07"
        izz="0.0034052" />
    </inertial>
    <visual>
      <origin
        xyz="0 0 0"
        rpy="0 0 0" />
      <geometry>
        <mesh
          filename="package://PP/meshes/base_link.STL" />
      </geometry>
      <material name="white"/>
    </visual>
    <collision>
      <origin
        xyz="0 0 0"
        rpy="0 0 0" />
      <geometry>
        <mesh
          filename="package://PP/meshes/low_qual/base_link.STL" />
      </geometry>
    </collision>
  </link>

  <link
    name="lf_shoulder_link">
    <inertial>
      <origin
        xyz="-0.030753 0.010778 0.045502"
        rpy="0 0 0" />
      <mass
        value="0.08" />
      <inertia
        ixx="1.9553E-05"
        ixy="2.0828E-07"
        ixz="3.218E-07"
        iyy="1.9066E-05"
        iyz="-9.7277E-07"
        izz="2.1805E-05" />
    </inertial>
    <visual>
      <origin
        xyz="0 0 0"
        rpy="0 0 0" />
      <geometry>
        <mesh
          filename="package://PP/meshes/lf_shoulder_link.STL" />
      </geometry>
      <material name="light-pink"/>
    </visual>
    <collision>
      <origin
        xyz="0 0 0"
        rpy="0 0 0" />
      <geometry>
        <mesh
          filename="package://PP/meshes/low_qual/lf_shoulder_link.STL" />
      </geometry>
    </collision>
  </link>

  <joint
    name="LF_ARMPIT"
    type="revolute">
    <origin
      xyz="0.086416 0.04808 0.020486"
      rpy="1.5796 5.1018E-05 3.1416" />
    <parent
      link="base_link" />
    <child
      link="lf_shoulder_link" />
    <axis
      xyz="1 5.1016E-05 0" />
    <limit
      lower="-0.6"
      upper="0.6"
      effort="10"
      velocity="0.188" />
  </joint>

  <link
    name="lf_thigh_link">
    <inertial>
      <origin
        xyz="0.059941 -0.034073 0.033487"
        rpy="0 0 0" />
      <mass
        value="0.2" />
      <inertia
        ixx="5.2643E-05"
        ixy="-6.8707E-06"
        ixz="-9.1036E-09"
        iyy="0.0002077"
        iyz="4.206E-10"
        izz="0.0001967" />
    </inertial>
    <visual>
      <origin
        xyz="0 0 0"
        rpy="0 0 0" />
      <geometry>
        <mesh
          filename="package://PP/meshes/lf_thigh_link.STL" />
      </geometry>
      <material
        name="light-pink"/>
    </visual>
    <collision>
      <origin
        xyz="0 0 0"
        rpy="0 0 0" />
      <geometry>
        <mesh
          filename="package://PP/meshes/low_qual/lf_thigh_link.STL" />
      </geometry>
    </collision>
  </link>

  <joint
    name="LF_ELBOW"
    type="revolute">
    <origin
      xyz="-0.0292763807105232 -0.0145596375104043 0.0194736909981926"
      rpy="0 0 -0.391100326154628" />
    <parent
      link="lf_shoulder_link" />
    <child
      link="lf_thigh_link" />
    <axis
      xyz="0 0 1" />
    <limit
      lower="-1"
      upper="1.2"
      effort="10"
      velocity="0.188" />
  </joint>

  <link
    name="lf_calf_link">
    <inertial>
      <origin
        xyz="-0.056274 -0.03107 0.031238"
        rpy="0 0 0" />
      <mass
        value="0.12" />
      <inertia
        ixx="2.7136E-05"
        ixy="6.5226E-06"
        ixz="-7.6949E-09"
        iyy="0.00025946"
        iyz="3.4777E-09"
        izz="0.00024892" />
    </inertial>
    <visual>
      <origin
        xyz="0 0 0"
        rpy="0 0 0" />
      <geometry>
        <mesh
          filename="package://PP/meshes/lf_calf_link.STL" />
      </geometry>
      <material
        name="light-pink"/>
    </visual>
    <collision>
      <origin
        xyz="0 0 0"
        rpy="0 0 0" />
      <geometry>
        <mesh
          filename="package://PP/meshes/low_qual/lf_calf_link.STL" />
      </geometry>
    </collision>
  </link>

  <joint
    name="LF_KNEE"
    type="revolute">
    <origin
      xyz="0.146923729810866 -0.0347427857925265 0.00221049130220088"
      rpy="0 0 0.847510405575288" />
    <parent
      link="lf_thigh_link" />
    <child
      link="lf_calf_link" />
    <axis
      xyz="0 0 1" />
    <limit
      lower="-0.6"
      upper="1.5"
      effort="10"
      velocity="0.188" />
  </joint>

  <link
    name="rf_shoulder_link">
    <inertial>
      <origin
        xyz="-0.030841 0.010778 -0.045501"
        rpy="0 0 0" />
      <mass
        value="0.08" />
      <inertia
        ixx="1.9552E-05"
        ixy="2.0806E-07"
        ixz="-3.2173E-07"
        iyy="1.9066E-05"
        iyz="9.7295E-07"
        izz="2.1805E-05" />
    </inertial>
    <visual>
      <origin
        xyz="0 0 0"
        rpy="0 0 0" />
      <geometry>
        <mesh
          filename="package://PP/meshes/rf_shoulder_link.STL" />
      </geometry>
      <material
        name="light-pink"/>
    </visual>
    <collision>
      <origin
        xyz="0 0 0"
        rpy="0 0 0" />
      <geometry>
        <mesh
          filename="package://PP/meshes/low_qual/rf_shoulder_link.STL" />
      </geometry>
    </collision>
  </link>

  <joint
    name="RF_ARMPIT"
    type="revolute">
    <origin
      xyz="0.086926 -0.04808 0.020486"
      rpy="1.574 5.102E-05 -3.1416" />
    <parent
      link="base_link" />
    <child
      link="rf_shoulder_link" />
    <axis
      xyz="1 5.102E-05 0" />
    <limit
      lower="-0.6"
      upper="0.6"
      effort="10"
      velocity="0.188" />
  </joint>

  <link
    name="rf_thigh_link">
    <inertial>
      <origin
        xyz="0.059941 -0.034073 -0.032689"
        rpy="0 0 0" />
      <mass
        value="0.2" />
      <inertia
        ixx="5.2643E-05"
        ixy="-6.8707E-06"
        ixz="-9.0904E-09"
        iyy="0.0002077"
        iyz="4.5082E-10"
        izz="0.0001967" />
    </inertial>
    <visual>
      <origin
        xyz="0 0 0"
        rpy="0 0 0" />
      <geometry>
        <mesh
          filename="package://PP/meshes/rf_thigh_link.STL" />
      </geometry>
      <material
        name="light-pink"/>
    </visual>
    <collision>
      <origin
        xyz="0 0 0"
        rpy="0 0 0" />
      <geometry>
        <mesh
          filename="package://PP/meshes/low_qual/rf_thigh_link.STL" />
      </geometry>
    </collision>
  </link>

  <joint
    name="RF_ELBOW"
    type="revolute">
    <origin
      xyz="-0.0292763926136173 -0.0145596376099831 -0.0201913965766899"
      rpy="0 0 -0.396320647708051" />
    <parent
      link="rf_shoulder_link" />
    <child
      link="rf_thigh_link" />
    <axis
      xyz="0 0 1" />
    <limit
      lower="-1"
      upper="1.2"
      effort="10"
      velocity="0.188" />
  </joint>

  <link
    name="rf_calf_link">
    <inertial>
      <origin
        xyz="-0.056274 -0.03107 -0.030468"
        rpy="0 0 0" />
      <mass
        value="0.12" />
      <inertia
        ixx="2.7136E-05"
        ixy="6.5227E-06"
        ixz="-7.3333E-09"
        iyy="0.00025946"
        iyz="3.4574E-09"
        izz="0.00024892" />
    </inertial>
    <visual>
      <origin
        xyz="0 0 0"
        rpy="0 0 0" />
      <geometry>
        <mesh
          filename="package://PP/meshes/rf_calf_link.STL" />
      </geometry>
      <material
        name="light-pink"/>
    </visual>
    <collision>
      <origin
        xyz="0 0 0"
        rpy="0 0 0" />
      <geometry>
        <mesh
          filename="package://PP/meshes/low_qual/rf_calf_link.STL" />
      </geometry>
    </collision>
  </link>
  <joint
    name="RF_KNEE"
    type="revolute">
    <origin
      xyz="0.146923729810897 -0.0347427857925089 -0.00226016980146514"
      rpy="0 0 0.855957326465464" />
    <parent
      link="rf_thigh_link" />
    <child
      link="rf_calf_link" />
    <axis
      xyz="0 0 1" />
    <limit
      lower="-0.6"
      upper="1.5"
      effort="10"
      velocity="0.188" />
  </joint>
  <link
    name="lb_shoulder_link">
    <inertial>
      <origin
        xyz="0.026809 0.010781 0.045502"
        rpy="0 0 0" />
      <mass
        value="0.08" />
      <inertia
        ixx="1.9553E-05"
        ixy="2.0828E-07"
        ixz="3.218E-07"
        iyy="1.9066E-05"
        iyz="-9.7277E-07"
        izz="2.1805E-05" />
    </inertial>
    <visual>
      <origin
        xyz="0 0 0"
        rpy="0 0 0" />
      <geometry>
        <mesh
          filename="package://PP/meshes/lb_shoulder_link.STL" />
      </geometry>
      <material
        name="light-pink"/>
    </visual>
    <collision>
      <origin
        xyz="0 0 0"
        rpy="0 0 0" />
      <geometry>
        <mesh
          filename="package://PP/meshes/low_qual/lb_shoulder_link.STL" />
      </geometry>
    </collision>
  </link>
  <joint
    name="LB_ARMPIT"
    type="revolute">
    <origin
      xyz="-0.090343 0.04808 0.020486"
      rpy="1.5771 5.1019E-05 -3.1416" />
    <parent
      link="base_link" />
    <child
      link="lb_shoulder_link" />
    <axis
      xyz="1 5.1018E-05 0" />
    <limit
      lower="-0.6"
      upper="0.6"
      effort="10"
      velocity="0.188" />
  </joint>
  <link
    name="lb_thigh_link">
    <inertial>
      <origin
        xyz="0.059941 -0.034073 0.033188"
        rpy="0 0 0" />
      <mass
        value="0.2" />
      <inertia
        ixx="5.2643E-05"
        ixy="-6.8707E-06"
        ixz="-9.0664E-09"
        iyy="0.0002077"
        iyz="3.9696E-10"
        izz="0.0001967" />
    </inertial>
    <visual>
      <origin
        xyz="0 0 0"
        rpy="0 0 0" />
      <geometry>
        <mesh
          filename="package://PP/meshes/lb_thigh_link.STL" />
      </geometry>
      <material
        name="light-pink"/>
    </visual>
    <collision>
      <origin
        xyz="0 0 0"
        rpy="0 0 0" />
      <geometry>
        <mesh
          filename="package://PP/meshes/low_qual/lb_thigh_link.STL" />
      </geometry>
    </collision>
  </link>
  <joint
    name="LB_ELBOW"
    type="revolute">
    <origin
      xyz="0.0282851953087068 -0.0145567008678925 0.0197727795166636"
      rpy="0 0 -0.403369036917515" />
    <parent
      link="lb_shoulder_link" />
    <child
      link="lb_thigh_link" />
    <axis
      xyz="0 0 1" />
    <limit
      lower="-1"
      upper="1.2"
      effort="10"
      velocity="0.188" />
  </joint>
  <link
    name="lb_calf_link">
    <inertial>
      <origin
        xyz="-0.056276 -0.031071 0.030904"
        rpy="0 0 0" />
      <mass
        value="0.12" />
      <inertia
        ixx="2.7136E-05"
        ixy="6.5208E-06"
        ixz="-9.4832E-09"
        iyy="0.00025948"
        iyz="3.3556E-09"
        izz="0.00024894" />
    </inertial>
    <visual>
      <origin
        xyz="0 0 0"
        rpy="0 0 0" />
      <geometry>
        <mesh
          filename="package://PP/meshes/lb_calf_link.STL" />
      </geometry>
      <material
        name="light-pink"/>
    </visual>
    <collision>
      <origin
        xyz="0 0 0"
        rpy="0 0 0" />
      <geometry>
        <mesh
          filename="package://PP/meshes/low_qual/lb_calf_link.STL" />
      </geometry>
    </collision>
  </link>
  <joint
    name="LB_KNEE"
    type="revolute">
    <origin
      xyz="0.146923729810866 -0.0347427857925263 0.0022460131535169"
      rpy="0 0 0.846105672174157" />
    <parent
      link="lb_thigh_link" />
    <child
      link="lb_calf_link" />
    <axis
      xyz="0 0 1" />
    <limit
      lower="-0.6"
      upper="1.5"
      effort="10"
      velocity="0.188" />
  </joint>
  <link
    name="rb_shoulder_link">
    <inertial>
      <origin
        xyz="0.026809 0.010781 -0.045502"
        rpy="0 0 0" />
      <mass
        value="0.8" />
      <inertia
        ixx="1.9552E-05"
        ixy="2.0806E-07"
        ixz="-3.2173E-07"
        iyy="1.9066E-05"
        iyz="9.7295E-07"
        izz="2.1805E-05" />
    </inertial>
    <visual>
      <origin
        xyz="0 0 0"
        rpy="0 0 0" />
      <geometry>
        <mesh
          filename="package://PP/meshes/rb_shoulder_link.STL" />
      </geometry>
      <material name="light-pink"/>
    </visual>
    <collision>
      <origin
        xyz="0 0 0"
        rpy="0 0 0" />
      <geometry>
        <mesh
          filename="package://PP/meshes/low_qual/rb_shoulder_link.STL" />
      </geometry>
    </collision>
  </link>
  <joint
    name="RB_ARMPIT"
    type="revolute">
    <origin
      xyz="-0.089832858326759 -0.048079999996991 0.0204860000530178"
      rpy="1.56726128115491 5.1020089459211E-05 3.14159265358979" />
    <parent
      link="base_link" />
    <child
      link="rb_shoulder_link" />
    <axis
      xyz="0.999999998698475 5.10197706500462E-05 0" />
    <limit
      lower="-0.6"
      upper="0.6"
      effort="10"
      velocity="0.188" />
  </joint>
  <link
    name="rb_thigh_link">
    <inertial>
      <origin
        xyz="0.059941 -0.034073 -0.03228"
        rpy="0 0 0" />
      <mass
        value="0.2" />
      <inertia
        ixx="5.2643E-05"
        ixy="-6.8707E-06"
        ixz="-9.0702E-09"
        iyy="0.0002077"
        iyz="4.531E-10"
        izz="0.0001967" />
    </inertial>
    <visual>
      <origin
        xyz="0 0 0"
        rpy="0 0 0" />
      <geometry>
        <mesh
          filename="package://PP/meshes/rb_thigh_link.STL" />
      </geometry>
      <material
        name="light-pink"/>
    </visual>
    <collision>
      <origin
        xyz="0 0 0"
        rpy="0 0 0" />
      <geometry>
        <mesh
          filename="package://PP/meshes/low_qual/rb_thigh_link.STL" />
      </geometry>
    </collision>
  </link>
  <joint
    name="RB_ELBOW"
    type="revolute">
    <origin
      xyz="0.0282851926369588 -0.014556700827701 -0.0206007488883525"
      rpy="0 0 -0.402912237027728" />
    <parent
      link="rb_shoulder_link" />
    <child
      link="rb_thigh_link" />
    <axis
      xyz="0 0 1" />
    <limit
      lower="-1"
      upper="1.2"
      effort="10"
      velocity="0.188" />
  </joint>
  <link
    name="rb_calf_link">
    <inertial>
      <origin
        xyz="-0.056274 -0.03107 -0.030041"
        rpy="0 0 0" />
      <mass
        value="0.12" />
      <inertia
        ixx="2.7136E-05"
        ixy="6.5224E-06"
        ixz="-6.7696E-09"
        iyy="0.00025946"
        iyz="3.5008E-09"
        izz="0.00024892" />
    </inertial>
    <visual>
      <origin
        xyz="0 0 0"
        rpy="0 0 0" />
      <geometry>
        <mesh
          filename="package://PP/meshes/rb_calf_link.STL" />
      </geometry>
      <material
        name="light-pink"/>
    </visual>
    <collision>
      <origin
        xyz="0 0 0"
        rpy="0 0 0" />
      <geometry>
        <mesh
          filename="package://PP/meshes/low_qual/rb_calf_link.STL" />
      </geometry>
    </collision>
  </link>
  <joint
    name="RB_KNEE"
    type="revolute">
    <origin
      xyz="0.146923729810898 -0.0347427857925087 -0.00227734285054983"
      rpy="0 0 0.845439714667136" />
    <parent
      link="rb_thigh_link" />
    <child
      link="rb_calf_link" />
    <axis
      xyz="0 0 1" />
    <limit
      lower="-0.6"
      upper="1.5"
      effort="10"
      velocity="0.188" />
  </joint>
</robot>