<?xml version="1.0"?>
<robot name="PinkPanther">

	<material name="dark-pink">
		<color rgba="1 0.2313 0.3843 1"/>
	</material>

	<material name="light-pink">
		<color rgba="0.7725 0.5411 0.7725 1"/>
	</material>

	<link name="body">
		<visual>
			<origin xyz="-0.1 0.22 -0.1" rpy="0 0 0"/>
			<geometry>
				<mesh filename="../meshes/base.STL"/>			
			</geometry>
			<material name="light-pink"/>
		</visual>
		<collision>
			<origin xyz="0 0 0.05" rpy="0 1.57075 0"/>
			<geometry>
				<cylinder length="0.3" radius="0.05"/>
			</geometry>
		</collision>
		<inertial>
			<origin xyz="0 0 0.15"/>
			<mass value="0.95228"/>
      		<inertia ixx="0.00090835" ixy="-9.0768E-05" ixz="-2.3727E-07" iyy="0.0034187" iyz="-1.9167E-07" izz="0.0028288"/>
    	</inertial>-->
	</link>

	<link name="right_front_shoulder">
		<visual>
			<origin xyz="-0.018 0.02 0.025" rpy="1.57075 0 3.1416"/>
			<geometry>
				<box size="0.05 0.05 0.05"/>
			</geometry>
			<material name="dark-pink"/>
		</visual>
		<collision>
			<origin xyz="-0.02 0.03 0.025" rpy="1.57075 0 3.1416"/>
			<geometry>
				<box size="0.05 0.05 0.05"/>
			</geometry>
		</collision>
		<!--<collision>
			<origin xyz="-0.036 0.01 0.01" rpy="1.57075 0 3.1416"/>
			<geometry>
				<mesh filename="../meshes/rightShoulder.STL"/>
			</geometry>
		</collision>-->
		<inertial>
	      <origin xyz="0.030839 0.010759 -0.045563"/>
	      <mass value="0.0824"/>
	      <inertia ixx="1.9553E-05" ixy="2.0806E-07" ixz="-3.2173E-07" iyy="1.9066E-05" iyz="9.7295E-07" izz="2.1806E-05"/>
    	</inertial>
	</link>

	<joint name="right_front_armpit" type="revolute">
		<origin xyz="0.15 -0.01 0"/>
		<parent link="body"/>
		<child link="right_front_shoulder"/>
		<axis xyz="1 0 0"/>
		<limit lower="-0.38" upper="5" effort="1000.0" velocity="50"/>
	</joint>


</robot>